<?xml version="1.0" ?>
<sdf version="1.9">
  <model name="right_angle_car_wsl_headless">
    <pose>0 0 0 0 0 0</pose>
    <self_collide>false</self_collide>

    <plugin filename="gz-sim-diff-drive-system" name="gz::sim::systems::DiffDrive">
      <left_joint>left_rear_wheel_joint</left_joint>
      <right_joint>right_rear_wheel_joint</right_joint>
      <wheel_separation>0.96</wheel_separation>
      <wheel_radius>0.18</wheel_radius>
      <odom_publish_frequency>50</odom_publish_frequency>
      <topic>/cmd_vel</topic>
      <odom_topic>/sensors/wheel_odom</odom_topic>
      <frame_id>world</frame_id>
      <child_frame_id>base_link</child_frame_id>
    </plugin>

    <link name="base_link">
      <inertial>
        <pose>0 0 0.32 0 0 0</pose>
        <mass>18.0</mass>
        <inertia>
          <ixx>1.2</ixx>
          <ixy>0</ixy>
          <ixz>0</ixz>
          <iyy>3.1</iyy>
          <iyz>0</iyz>
          <izz>3.4</izz>
        </inertia>
      </inertial>
      <collision name="chassis_collision">
        <pose>0 0 0.32 0 0 0</pose>
        <geometry>
          <box>
            <size>1.65 0.82 0.22</size>
          </box>
        </geometry>
      </collision>
      <visual name="chassis_visual">
        <pose>0 0 0.32 0 0 0</pose>
        <geometry>
          <box>
            <size>1.65 0.82 0.22</size>
          </box>
        </geometry>
        <material>
          <ambient>0.85 0.04 0.04 1</ambient>
          <diffuse>0.85 0.04 0.04 1</diffuse>
        </material>
      </visual>
    </link>

    <link name="left_rear_wheel_link">
      <pose relative_to="base_link">-0.52 0.48 0.18 0 0 0</pose>
      <inertial>
        <mass>1.2</mass>
        <inertia>
          <ixx>0.02</ixx>
          <ixy>0</ixy>
          <ixz>0</ixz>
          <iyy>0.02</iyy>
          <iyz>0</iyz>
          <izz>0.02</izz>
        </inertia>
      </inertial>
      <collision name="collision">
        <pose>0 0 0 1.57079632679 0 0</pose>
        <geometry>
          <cylinder>
            <radius>0.18</radius>
            <length>0.08</length>
          </cylinder>
        </geometry>
        <surface>
          <friction>
            <ode>
              <mu>1.3</mu>
              <mu2>1.3</mu2>
            </ode>
          </friction>
        </surface>
      </collision>
      <visual name="visual">
        <pose>0 0 0 1.57079632679 0 0</pose>
        <geometry>
          <cylinder>
            <radius>0.18</radius>
            <length>0.08</length>
          </cylinder>
        </geometry>
        <material>
          <ambient>0.01 0.01 0.012 1</ambient>
          <diffuse>0.01 0.01 0.012 1</diffuse>
        </material>
      </visual>
    </link>

    <link name="right_rear_wheel_link">
      <pose relative_to="base_link">-0.52 -0.48 0.18 0 0 0</pose>
      <inertial>
        <mass>1.2</mass>
        <inertia>
          <ixx>0.02</ixx>
          <ixy>0</ixy>
          <ixz>0</ixz>
          <iyy>0.02</iyy>
          <iyz>0</iyz>
          <izz>0.02</izz>
        </inertia>
      </inertial>
      <collision name="collision">
        <pose>0 0 0 1.57079632679 0 0</pose>
        <geometry>
          <cylinder>
            <radius>0.18</radius>
            <length>0.08</length>
          </cylinder>
        </geometry>
        <surface>
          <friction>
            <ode>
              <mu>1.3</mu>
              <mu2>1.3</mu2>
            </ode>
          </friction>
        </surface>
      </collision>
      <visual name="visual">
        <pose>0 0 0 1.57079632679 0 0</pose>
        <geometry>
          <cylinder>
            <radius>0.18</radius>
            <length>0.08</length>
          </cylinder>
        </geometry>
        <material>
          <ambient>0.01 0.01 0.012 1</ambient>
          <diffuse>0.01 0.01 0.012 1</diffuse>
        </material>
      </visual>
    </link>

    <link name="left_front_wheel_link">
      <pose relative_to="base_link">0.52 0.48 0.18 0 0 0</pose>
      <inertial>
        <mass>1.2</mass>
        <inertia>
          <ixx>0.02</ixx>
          <ixy>0</ixy>
          <ixz>0</ixz>
          <iyy>0.02</iyy>
          <iyz>0</iyz>
          <izz>0.02</izz>
        </inertia>
      </inertial>
      <collision name="collision">
        <pose>0 0 0 1.57079632679 0 0</pose>
        <geometry>
          <cylinder>
            <radius>0.18</radius>
            <length>0.08</length>
          </cylinder>
        </geometry>
        <surface>
          <friction>
            <ode>
              <mu>0.4</mu>
              <mu2>0.4</mu2>
            </ode>
          </friction>
        </surface>
      </collision>
      <visual name="visual">
        <pose>0 0 0 1.57079632679 0 0</pose>
        <geometry>
          <cylinder>
            <radius>0.18</radius>
            <length>0.08</length>
          </cylinder>
        </geometry>
        <material>
          <ambient>0.01 0.01 0.012 1</ambient>
          <diffuse>0.01 0.01 0.012 1</diffuse>
        </material>
      </visual>
    </link>

    <link name="right_front_wheel_link">
      <pose relative_to="base_link">0.52 -0.48 0.18 0 0 0</pose>
      <inertial>
        <mass>1.2</mass>
        <inertia>
          <ixx>0.02</ixx>
          <ixy>0</ixy>
          <ixz>0</ixz>
          <iyy>0.02</iyy>
          <iyz>0</iyz>
          <izz>0.02</izz>
        </inertia>
      </inertial>
      <collision name="collision">
        <pose>0 0 0 1.57079632679 0 0</pose>
        <geometry>
          <cylinder>
            <radius>0.18</radius>
            <length>0.08</length>
          </cylinder>
        </geometry>
        <surface>
          <friction>
            <ode>
              <mu>0.4</mu>
              <mu2>0.4</mu2>
            </ode>
          </friction>
        </surface>
      </collision>
      <visual name="visual">
        <pose>0 0 0 1.57079632679 0 0</pose>
        <geometry>
          <cylinder>
            <radius>0.18</radius>
            <length>0.08</length>
          </cylinder>
        </geometry>
        <material>
          <ambient>0.01 0.01 0.012 1</ambient>
          <diffuse>0.01 0.01 0.012 1</diffuse>
        </material>
      </visual>
    </link>

    <joint name="left_rear_wheel_joint" type="revolute">
      <parent>base_link</parent>
      <child>left_rear_wheel_link</child>
      <axis>
        <xyz>0 1 0</xyz>
        <limit>
          <lower>-1e16</lower>
          <upper>1e16</upper>
          <effort>70</effort>
          <velocity>40</velocity>
        </limit>
        <dynamics>
          <damping>0.05</damping>
          <friction>0.02</friction>
        </dynamics>
      </axis>
    </joint>

    <joint name="right_rear_wheel_joint" type="revolute">
      <parent>base_link</parent>
      <child>right_rear_wheel_link</child>
      <axis>
        <xyz>0 1 0</xyz>
        <limit>
          <lower>-1e16</lower>
          <upper>1e16</upper>
          <effort>70</effort>
          <velocity>40</velocity>
        </limit>
        <dynamics>
          <damping>0.05</damping>
          <friction>0.02</friction>
        </dynamics>
      </axis>
    </joint>

    <joint name="left_front_wheel_joint" type="revolute">
      <parent>base_link</parent>
      <child>left_front_wheel_link</child>
      <axis>
        <xyz>0 1 0</xyz>
        <limit>
          <lower>-1e16</lower>
          <upper>1e16</upper>
          <effort>30</effort>
          <velocity>40</velocity>
        </limit>
        <dynamics>
          <damping>0.05</damping>
          <friction>0.02</friction>
        </dynamics>
      </axis>
    </joint>

    <joint name="right_front_wheel_joint" type="revolute">
      <parent>base_link</parent>
      <child>right_front_wheel_link</child>
      <axis>
        <xyz>0 1 0</xyz>
        <limit>
          <lower>-1e16</lower>
          <upper>1e16</upper>
          <effort>30</effort>
          <velocity>40</velocity>
        </limit>
        <dynamics>
          <damping>0.05</damping>
          <friction>0.02</friction>
        </dynamics>
      </axis>
    </joint>

    <link name="gps_link">
      <pose relative_to="base_link">-0.25 0 0.78 0 0 0</pose>
      <sensor name="gps_sensor" type="navsat">
        <topic>/sensors/gps/fix</topic>
        <frame_id>gps_link</frame_id>
        <always_on>true</always_on>
        <update_rate>10</update_rate>
        <visualize>false</visualize>
        <navsat>
          <position_sensing>
            <horizontal>
              <noise type="gaussian">
                <mean>0.0</mean>
                <stddev>0.35</stddev>
              </noise>
            </horizontal>
            <vertical>
              <noise type="gaussian">
                <mean>0.0</mean>
                <stddev>0.5</stddev>
              </noise>
            </vertical>
          </position_sensing>
        </navsat>
      </sensor>
    </link>

    <link name="imu_link">
      <pose relative_to="base_link">0 0 0.36 0 0 0</pose>
      <sensor name="imu_sensor" type="imu">
        <topic>/sensors/imu/data_raw</topic>
        <frame_id>imu_link</frame_id>
        <always_on>true</always_on>
        <update_rate>100</update_rate>
        <visualize>false</visualize>
        <imu>
          <angular_velocity>
            <x>
              <noise type="gaussian">
                <mean>0.0</mean>
                <stddev>0.002</stddev>
              </noise>
            </x>
            <y>
              <noise type="gaussian">
                <mean>0.0</mean>
                <stddev>0.002</stddev>
              </noise>
            </y>
            <z>
              <noise type="gaussian">
                <mean>0.0</mean>
                <stddev>0.002</stddev>
              </noise>
            </z>
          </angular_velocity>
          <linear_acceleration>
            <x>
              <noise type="gaussian">
                <mean>0.0</mean>
                <stddev>0.03</stddev>
              </noise>
            </x>
            <y>
              <noise type="gaussian">
                <mean>0.0</mean>
                <stddev>0.03</stddev>
              </noise>
            </y>
            <z>
              <noise type="gaussian">
                <mean>0.0</mean>
                <stddev>0.03</stddev>
              </noise>
            </z>
          </linear_acceleration>
        </imu>
      </sensor>
    </link>

    <link name="magnetometer_link">
      <pose relative_to="base_link">0.15 0 0.62 0 0 0</pose>
      <sensor name="magnetometer_sensor" type="magnetometer">
        <topic>/sensors/magnetic_field</topic>
        <frame_id>magnetometer_link</frame_id>
        <always_on>true</always_on>
        <update_rate>30</update_rate>
        <visualize>false</visualize>
        <magnetometer>
          <x>
            <noise type="gaussian">
              <mean>0.0</mean>
              <stddev>0.000001</stddev>
            </noise>
          </x>
          <y>
            <noise type="gaussian">
              <mean>0.0</mean>
              <stddev>0.000001</stddev>
            </noise>
          </y>
          <z>
            <noise type="gaussian">
              <mean>0.0</mean>
              <stddev>0.000001</stddev>
            </noise>
          </z>
        </magnetometer>
      </sensor>
    </link>

    <joint name="gps_joint" type="fixed">
      <parent>base_link</parent>
      <child>gps_link</child>
    </joint>
    <joint name="imu_joint" type="fixed">
      <parent>base_link</parent>
      <child>imu_link</child>
    </joint>
    <joint name="magnetometer_joint" type="fixed">
      <parent>base_link</parent>
      <child>magnetometer_link</child>
    </joint>
  </model>
</sdf>
